<?xml version="1.0" ?>
<!-- =================================================================================== -->
<!-- |    This document was autogenerated by xacro from kubo.urdf.xacro                | -->
<!-- |    EDITING THIS FILE BY HAND IS NOT RECOMMENDED                                 | -->
<!-- =================================================================================== -->
<robot name="kubo" xmlns:xacro="http://www.ros.org/wiki/xacro">
  <gazebo>
    <plugin filename="libgazebo_ros_control.so" name="gazebo_ros_control"/>
  </gazebo>
  <!-- camera -->
  <gazebo reference="camera">
    <material>Gazebo/Green</material>
    <sensor name="camera1" type="camera">
      <update_rate>30.0</update_rate>
      <camera name="head">
        <horizontal_fov>1.3962634</horizontal_fov>
        <image>
          <width>800</width>
          <height>800</height>
          <format>R8G8B8</format>
        </image>
        <clip>
          <near>0.02</near>
          <far>300</far>
        </clip>
      </camera>
      <plugin filename="libgazebo_ros_camera.so" name="camera_controller">
        <alwaysOn>true</alwaysOn>
        <updateRate>0.0</updateRate>
        <cameraName>tractor_sim/camera1</cameraName>
        <imageTopicName>image_raw</imageTopicName>
        <cameraInfoTopicName>camera_info</cameraInfoTopicName>
        <frameName>camera</frameName>
        <hackBaseline>0.07</hackBaseline>
        <distortionK1>0.0</distortionK1>
        <distortionK2>0.0</distortionK2>
        <distortionK3>0.0</distortionK3>
        <distortionT1>0.0</distortionT1>
        <distortionT2>0.0</distortionT2>
      </plugin>
    </sensor>
  </gazebo>
  <!-- hokuyo -->
  <gazebo reference="hokuyo">
    <sensor name="head_hokuyo_sensor" type="ray">
      <pose>0 0 0 0 0 0</pose>
      <visualize>true</visualize>
      <update_rate>40</update_rate>
      <ray>
        <scan>
          <horizontal>
            <samples>720</samples>
            <resolution>1</resolution>
            <min_angle>-1.570796</min_angle>
            <max_angle>1.570796</max_angle>
          </horizontal>
        </scan>
        <range>
          <min>0.10</min>
          <max>30.0</max>
          <resolution>0.01</resolution>
        </range>
        <noise>
          <type>gaussian</type>
          <!-- Noise parameters based on published spec for Hokuyo laser
               achieving "+-30mm" accuracy at range < 10m.  A mean of 0.0m and
               stddev of 0.01m will put 99.7% of samples within 0.03m of the true
               reading. -->
          <mean>0.0</mean>
          <stddev>0.01</stddev>
        </noise>
      </ray>
      <plugin filename="libgazebo_ros_laser.so" name="gazebo_ros_head_hokuyo_controller">
        <topicName>/scan</topicName>
        <frameName>hokuyo</frameName>
      </plugin>
    </sensor>
  </gazebo>
  <!-- TODO: Look through logs on launch to set more params for imu, camera, and laser -->
  <gazebo>
    <plugin filename="libhector_gazebo_ros_gps.so" name="gazebo_ros_gps">
      <updateRate>4.0</updateRate>
      <bodyName>hemisphere_gps</bodyName>
      <frameId>sensor</frameId>
      <topicName>tractor_sim/hemisphere_gps/fix</topicName>
      <velocityTopicName>/hemisphere_gps/fix_velocity</velocityTopicName>
      <referenceLatitude>-30.06022459407145675</referenceLatitude>
      <referenceLongitude>-51.173913575780311191</referenceLongitude>
      <referenceHeading>90</referenceHeading>
      <referenceAltitude>10</referenceAltitude>
      <offset>0 0 0</offset>
      <drift>0.001 0.001 0.001</drift>
      <gaussianNoise>0.05 0.05 0.05</gaussianNoise>
      <velocityDrift>0.001 0.001 0.001</velocityDrift>
      <velocityGaussianNoise>0.5 0.5 0.5</velocityGaussianNoise>
      <!--                <drift>0.001 0.001 0.001</drift>-->
      <!--                <gaussianNoise>0.01 0.01 0.01</gaussianNoise>-->
      <!--                <velocityDrift>0 0 0</velocityDrift>-->
      <!--                <velocityGaussianNoise>0.05 0.05 0.05</velocityGaussianNoise>-->
    </plugin>
  </gazebo>
  <gazebo>
    <plugin filename="libhector_gazebo_ros_gps.so" name="gazebo_ros_gps">
      <updateRate>4.0</updateRate>
      <bodyName>rtk_gps</bodyName>
      <frameId>sensor</frameId>
      <topicName>tractor_sim/rtk_gps/fix</topicName>
      <velocityTopicName>/rtk_gps/fix_velocity</velocityTopicName>
      <referenceLatitude>-30.06022459407145675</referenceLatitude>
      <referenceLongitude>-51.173913575780311191</referenceLongitude>
      <referenceHeading>90</referenceHeading>
      <referenceAltitude>10</referenceAltitude>
      <offset>0 0 0</offset>
      <drift>0.001 0.001 0.001</drift>
      <gaussianNoise>0.05 0.05 0.05</gaussianNoise>
      <velocityDrift>0.001 0.001 0.001</velocityDrift>
      <velocityGaussianNoise>0.5 0.5 0.5</velocityGaussianNoise>
      <!--                <drift>0.001 0.001 0.001</drift>-->
      <!--                <gaussianNoise>0.01 0.01 0.01</gaussianNoise>-->
      <!--                <velocityDrift>0 0 0</velocityDrift>-->
      <!--                <velocityGaussianNoise>0.05 0.05 0.05</velocityGaussianNoise>-->
    </plugin>
  </gazebo>
  <gazebo>
    <plugin filename="libgazebo_ros_imu.so" name="imu_plugin">
      <alwaysOn>true</alwaysOn>
      <bodyName>imu</bodyName>
      <topicName>tractor_sim/imu</topicName>
      <serviceName>imu_service</serviceName>
      <gaussianNoise>0.0</gaussianNoise>
      <updateRate>20.0</updateRate>
    </plugin>
  </gazebo>
  <material name="chassis_mat">
    <color rgba="0.5 0.5 0.5 1"/>
  </material>
  <material name="tire_mat">
    <color rgba="0 0 0 1"/>
  </material>
  <!-- Z Distance from ground -->
  <!-- For inertia measurements -->
  <!-- base_link must have geometry so that its axes can be displayed in
       rviz. -->
  <link name="base_link">
    <visual>
      <geometry>
        <box size="0.01 0.01 0.01"/>
      </geometry>
      <material name="chassis_mat"/>
    </visual>
  </link>
  <gazebo reference="base_link">
    <material>Gazebo/Grey</material>
  </gazebo>
  <!-- Chassis -->
  <link name="chassis">
    <visual>
      <origin xyz="0.75 0 0.25"/>
      <!--Defualt: 0 0 ${-chassis_height / 2} -->
      <geometry>
        <box size="1.5 0.3 0.1"/>
      </geometry>
      <material name="chassis_mat"/>
    </visual>
    <collision>
      <origin xyz="0.75 0 0.25"/>
      <geometry>
        <box size="1.5 0.3 0.1"/>
      </geometry>
    </collision>
    <inertial>
      <origin xyz="0 0 -0.05"/>
      <mass value="2.788"/>
      <inertia ixx="0.0232333333333" ixy="0" ixz="0" iyy="0.525073333333" iyz="0" izz="0.54366"/>
    </inertial>
  </link>
  <gazebo reference="chassis">
    <material>Gazebo/Grey</material>
  </gazebo>
  <joint name="base_link_to_chassis" type="fixed">
    <parent link="base_link"/>
    <child link="chassis"/>
  </joint>
  <joint name="left_front_shock" type="prismatic">
    <parent link="chassis"/>
    <child link="left_steering_link"/>
    <origin xyz="1.5                    0.4                    0.25"/>
    <!-- Default: ${fr_reflect * wheelbase / 2}
                                ${lr_reflect * ((hex_hub_dist / 2) - axle_length)}
                                ${(wheel_travel / 2) - shock_z_offset}"-->
    <axis xyz="0 0 -1"/>
    <limit effort="125106" lower="0.0" upper="0.0" velocity="1000000"/>
  </joint>
  <transmission name="left_front_shock_trans">
    <type>transmission_interface/SimpleTransmission</type>
    <joint name="left_front_shock">
      <hardwareInterface>hardware_interface/EffortJointInterface</hardwareInterface>
    </joint>
    <actuator name="left_front_shock_act">
      <!-- This hardwareInterface element exists for compatibility
             with ROS Hydro. -->
      <hardwareInterface>hardware_interface/EffortJointInterface</hardwareInterface>
      <mechanicalReduction>1</mechanicalReduction>
    </actuator>
  </transmission>
  <link name="left_steering_link">
    <inertial>
      <mass value="0.001"/>
      <inertia ixx="0.001" ixy="0" ixz="0" iyy="0.001" iyz="0" izz="0.001"/>
    </inertial>
  </link>
  <joint name="left_steering_joint" type="revolute">
    <parent link="left_steering_link"/>
    <child link="left_front_axle_carrier"/>
    <axis xyz="0 0 1"/>
    <limit effort="5649" lower="-0.785398163" upper="0.785398163" velocity="4553"/>
  </joint>
  <transmission name="left_steering_trans">
    <type>transmission_interface/SimpleTransmission</type>
    <joint name="left_steering_joint">
      <hardwareInterface>hardware_interface/EffortJointInterface</hardwareInterface>
    </joint>
    <actuator name="left_steering_act">
      <!-- This hardwareInterface element exists for compatibility
             with ROS Hydro. -->
      <hardwareInterface>hardware_interface/EffortJointInterface</hardwareInterface>
      <mechanicalReduction>1</mechanicalReduction>
    </actuator>
  </transmission>
  <link name="left_front_axle_carrier">
    <inertial>
      <mass value="0.001"/>
      <inertia ixx="0.001" ixy="0" ixz="0" iyy="0.001" iyz="0" izz="0.001"/>
    </inertial>
  </link>
  <!-- The left and right axles have the same axis so that identical
         rotation values cause the wheels to rotate in the same direction. -->
  <joint name="left_front_axle" type="continuous">
    <parent link="left_front_axle_carrier"/>
    <child link="left_front_wheel"/>
    <origin rpy="1.57079633 0 0"/>
    <axis xyz="0 0 -1"/>
    <limit effort="512766" velocity="2448696"/>
  </joint>
  <transmission name="left_front_axle_trans">
    <type>transmission_interface/SimpleTransmission</type>
    <joint name="left_front_axle">
      <hardwareInterface>hardware_interface/EffortJointInterface</hardwareInterface>
    </joint>
    <actuator name="left_front_axle_act">
      <!-- This hardwareInterface element exists for compatibility
             with ROS Hydro. -->
      <hardwareInterface>hardware_interface/EffortJointInterface</hardwareInterface>
      <mechanicalReduction>1</mechanicalReduction>
    </actuator>
  </transmission>
  <link name="left_front_wheel">
    <visual>
      <origin xyz="0                      0.0                      0"/>
      <geometry>
        <cylinder length="0.15" radius="0.25"/>
      </geometry>
      <material name="tire_mat"/>
    </visual>
    <collision>
      <origin xyz="0                      0.0                      0"/>
      <geometry>
        <cylinder length="0.15" radius="0.25"/>
      </geometry>
    </collision>
    <inertial>
      <mass value="0.29"/>
      <inertia ixx="0.005243854501" ixy="0" ixz="0" iyy="0.005243854501" iyz="0" izz="0.009400209002"/>
    </inertial>
  </link>
  <gazebo reference="left_front_wheel">
    <material>Gazebo/Black</material>
  </gazebo>
  <joint name="right_front_shock" type="prismatic">
    <parent link="chassis"/>
    <child link="right_steering_link"/>
    <origin xyz="1.5                    -0.4                    0.25"/>
    <!-- Default: ${fr_reflect * wheelbase / 2}
                                ${lr_reflect * ((hex_hub_dist / 2) - axle_length)}
                                ${(wheel_travel / 2) - shock_z_offset}"-->
    <axis xyz="0 0 -1"/>
    <limit effort="125106" lower="0.0" upper="0.0" velocity="1000000"/>
  </joint>
  <transmission name="right_front_shock_trans">
    <type>transmission_interface/SimpleTransmission</type>
    <joint name="right_front_shock">
      <hardwareInterface>hardware_interface/EffortJointInterface</hardwareInterface>
    </joint>
    <actuator name="right_front_shock_act">
      <!-- This hardwareInterface element exists for compatibility
             with ROS Hydro. -->
      <hardwareInterface>hardware_interface/EffortJointInterface</hardwareInterface>
      <mechanicalReduction>1</mechanicalReduction>
    </actuator>
  </transmission>
  <link name="right_steering_link">
    <inertial>
      <mass value="0.001"/>
      <inertia ixx="0.001" ixy="0" ixz="0" iyy="0.001" iyz="0" izz="0.001"/>
    </inertial>
  </link>
  <joint name="right_steering_joint" type="revolute">
    <parent link="right_steering_link"/>
    <child link="right_front_axle_carrier"/>
    <axis xyz="0 0 1"/>
    <limit effort="5649" lower="-0.785398163" upper="0.785398163" velocity="4553"/>
  </joint>
  <transmission name="right_steering_trans">
    <type>transmission_interface/SimpleTransmission</type>
    <joint name="right_steering_joint">
      <hardwareInterface>hardware_interface/EffortJointInterface</hardwareInterface>
    </joint>
    <actuator name="right_steering_act">
      <!-- This hardwareInterface element exists for compatibility
             with ROS Hydro. -->
      <hardwareInterface>hardware_interface/EffortJointInterface</hardwareInterface>
      <mechanicalReduction>1</mechanicalReduction>
    </actuator>
  </transmission>
  <link name="right_front_axle_carrier">
    <inertial>
      <mass value="0.001"/>
      <inertia ixx="0.001" ixy="0" ixz="0" iyy="0.001" iyz="0" izz="0.001"/>
    </inertial>
  </link>
  <!-- The left and right axles have the same axis so that identical
         rotation values cause the wheels to rotate in the same direction. -->
  <joint name="right_front_axle" type="continuous">
    <parent link="right_front_axle_carrier"/>
    <child link="right_front_wheel"/>
    <origin rpy="1.57079633 0 0"/>
    <axis xyz="0 0 -1"/>
    <limit effort="512766" velocity="2448696"/>
  </joint>
  <transmission name="right_front_axle_trans">
    <type>transmission_interface/SimpleTransmission</type>
    <joint name="right_front_axle">
      <hardwareInterface>hardware_interface/EffortJointInterface</hardwareInterface>
    </joint>
    <actuator name="right_front_axle_act">
      <!-- This hardwareInterface element exists for compatibility
             with ROS Hydro. -->
      <hardwareInterface>hardware_interface/EffortJointInterface</hardwareInterface>
      <mechanicalReduction>1</mechanicalReduction>
    </actuator>
  </transmission>
  <link name="right_front_wheel">
    <visual>
      <origin xyz="0                      -0.0                      0"/>
      <geometry>
        <cylinder length="0.15" radius="0.25"/>
      </geometry>
      <material name="tire_mat"/>
    </visual>
    <collision>
      <origin xyz="0                      -0.0                      0"/>
      <geometry>
        <cylinder length="0.15" radius="0.25"/>
      </geometry>
    </collision>
    <inertial>
      <mass value="0.29"/>
      <inertia ixx="0.005243854501" ixy="0" ixz="0" iyy="0.005243854501" iyz="0" izz="0.009400209002"/>
    </inertial>
  </link>
  <gazebo reference="right_front_wheel">
    <material>Gazebo/Black</material>
  </gazebo>
  <joint name="left_rear_shock" type="prismatic">
    <parent link="chassis"/>
    <child link="left_rear_axle_carrier"/>
    <origin xyz="0.0                    0.4                    0.35"/>
    <!-- Default: ${fr_reflect * wheelbase / 2}
                                ${lr_reflect * ((hex_hub_dist / 2) - axle_length)}
                                ${(wheel_travel / 2) - shock_z_offset}"-->
    <axis xyz="0 0 -1"/>
    <limit effort="125106" lower="0.0" upper="0.0" velocity="1000000"/>
  </joint>
  <transmission name="left_rear_shock_trans">
    <type>transmission_interface/SimpleTransmission</type>
    <joint name="left_rear_shock">
      <hardwareInterface>hardware_interface/EffortJointInterface</hardwareInterface>
    </joint>
    <actuator name="left_rear_shock_act">
      <!-- This hardwareInterface element exists for compatibility
             with ROS Hydro. -->
      <hardwareInterface>hardware_interface/EffortJointInterface</hardwareInterface>
      <mechanicalReduction>1</mechanicalReduction>
    </actuator>
  </transmission>
  <link name="left_rear_axle_carrier">
    <inertial>
      <mass value="0.001"/>
      <inertia ixx="0.001" ixy="0" ixz="0" iyy="0.001" iyz="0" izz="0.001"/>
    </inertial>
  </link>
  <!-- The left and right axles have the same axis so that identical
         rotation values cause the wheels to rotate in the same direction. -->
  <joint name="left_rear_axle" type="continuous">
    <parent link="left_rear_axle_carrier"/>
    <child link="left_rear_wheel"/>
    <origin rpy="1.57079633 0 0"/>
    <axis xyz="0 0 -1"/>
    <limit effort="512766" velocity="2448696"/>
  </joint>
  <transmission name="left_rear_axle_trans">
    <type>transmission_interface/SimpleTransmission</type>
    <joint name="left_rear_axle">
      <hardwareInterface>hardware_interface/EffortJointInterface</hardwareInterface>
    </joint>
    <actuator name="left_rear_axle_act">
      <!-- This hardwareInterface element exists for compatibility
             with ROS Hydro. -->
      <hardwareInterface>hardware_interface/EffortJointInterface</hardwareInterface>
      <mechanicalReduction>1</mechanicalReduction>
    </actuator>
  </transmission>
  <link name="left_rear_wheel">
    <visual>
      <origin xyz="0                      0.0                      0"/>
      <geometry>
        <cylinder length="0.2" radius="0.35"/>
      </geometry>
      <material name="tire_mat"/>
    </visual>
    <collision>
      <origin xyz="0                      0.0                      0"/>
      <geometry>
        <cylinder length="0.2" radius="0.35"/>
      </geometry>
    </collision>
    <inertial>
      <mass value="0.29"/>
      <inertia ixx="0.0100167711677" ixy="0" ixz="0" iyy="0.0100167711677" iyz="0" izz="0.018100209002"/>
    </inertial>
  </link>
  <gazebo reference="left_rear_wheel">
    <material>Gazebo/Black</material>
  </gazebo>
  <joint name="right_rear_shock" type="prismatic">
    <parent link="chassis"/>
    <child link="right_rear_axle_carrier"/>
    <origin xyz="0.0                    -0.4                    0.35"/>
    <!-- Default: ${fr_reflect * wheelbase / 2}
                                ${lr_reflect * ((hex_hub_dist / 2) - axle_length)}
                                ${(wheel_travel / 2) - shock_z_offset}"-->
    <axis xyz="0 0 -1"/>
    <limit effort="125106" lower="0.0" upper="0.0" velocity="1000000"/>
  </joint>
  <transmission name="right_rear_shock_trans">
    <type>transmission_interface/SimpleTransmission</type>
    <joint name="right_rear_shock">
      <hardwareInterface>hardware_interface/EffortJointInterface</hardwareInterface>
    </joint>
    <actuator name="right_rear_shock_act">
      <!-- This hardwareInterface element exists for compatibility
             with ROS Hydro. -->
      <hardwareInterface>hardware_interface/EffortJointInterface</hardwareInterface>
      <mechanicalReduction>1</mechanicalReduction>
    </actuator>
  </transmission>
  <link name="right_rear_axle_carrier">
    <inertial>
      <mass value="0.001"/>
      <inertia ixx="0.001" ixy="0" ixz="0" iyy="0.001" iyz="0" izz="0.001"/>
    </inertial>
  </link>
  <!-- The left and right axles have the same axis so that identical
         rotation values cause the wheels to rotate in the same direction. -->
  <joint name="right_rear_axle" type="continuous">
    <parent link="right_rear_axle_carrier"/>
    <child link="right_rear_wheel"/>
    <origin rpy="1.57079633 0 0"/>
    <axis xyz="0 0 -1"/>
    <limit effort="512766" velocity="2448696"/>
  </joint>
  <transmission name="right_rear_axle_trans">
    <type>transmission_interface/SimpleTransmission</type>
    <joint name="right_rear_axle">
      <hardwareInterface>hardware_interface/EffortJointInterface</hardwareInterface>
    </joint>
    <actuator name="right_rear_axle_act">
      <!-- This hardwareInterface element exists for compatibility
             with ROS Hydro. -->
      <hardwareInterface>hardware_interface/EffortJointInterface</hardwareInterface>
      <mechanicalReduction>1</mechanicalReduction>
    </actuator>
  </transmission>
  <link name="right_rear_wheel">
    <visual>
      <origin xyz="0                      -0.0                      0"/>
      <geometry>
        <cylinder length="0.2" radius="0.35"/>
      </geometry>
      <material name="tire_mat"/>
    </visual>
    <collision>
      <origin xyz="0                      -0.0                      0"/>
      <geometry>
        <cylinder length="0.2" radius="0.35"/>
      </geometry>
    </collision>
    <inertial>
      <mass value="0.29"/>
      <inertia ixx="0.0100167711677" ixy="0" ixz="0" iyy="0.0100167711677" iyz="0" izz="0.018100209002"/>
    </inertial>
  </link>
  <gazebo reference="right_rear_wheel">
    <material>Gazebo/Black</material>
  </gazebo>
  <link name="camera">
    <collision>
      <origin rpy="0 0 0" xyz="0 0 0"/>
      <geometry>
        <box size="0.05 0.05 0.05"/>
        <!-- CHANGE LATER-->
      </geometry>
    </collision>
    <visual>
      <origin rpy="0 0 0" xyz="0 0 0"/>
      <geometry>
        <box size="0.05 0.05 0.05"/>
      </geometry>
      <material name="green"/>
    </visual>
    <inertial>
      <mass value="0.1"/>
      <origin rpy="0 0 0" xyz="0 0 0"/>
      <box_inertia m="0.1" x="0.1" y="0.1" z="0.1"/>
      <inertia ixx="1e-6" ixy="0" ixz="0" iyy="1e-6" iyz="0" izz="1e-6"/>
    </inertial>
  </link>
  <joint name="camera_joint" type="fixed">
    <axis xyz="0 1 0"/>
    <origin rpy="0 0 0" xyz="2.08 0 1.04"/>
    <!-- CHANGE LATER-->
    <parent link="base_link"/>
    <child link="camera"/>
  </joint>
  <link name="hokuyo">
    <collision>
      <origin rpy="0 0 0" xyz="0 0 0"/>
      <geometry>
        <box size="0.05 0.05 0.05"/>
        <!-- CHANGE LATER-->
      </geometry>
    </collision>
    <visual>
      <origin rpy="0 0 0" xyz="0 0 0"/>
      <geometry>
        <box size="0.05 0.05 0.05"/>
      </geometry>
      <material name="green"/>
    </visual>
    <inertial>
      <mass value="0.1"/>
      <origin rpy="0 0 0" xyz="0 0 0"/>
      <box_inertia m="0.1" x="0.1" y="0.1" z="0.1"/>
      <inertia ixx="1e-6" ixy="0" ixz="0" iyy="1e-6" iyz="0" izz="1e-6"/>
    </inertial>
  </link>
  <joint name="hokuyo_joint" type="fixed">
    <axis xyz="0 1 0"/>
    <origin rpy="0 0.157 0" xyz="2.02 0 1.19"/>
    <!-- CHANGE LATER-->
    <parent link="base_link"/>
    <child link="hokuyo"/>
  </joint>
  <link name="imu">
    <collision>
      <origin rpy="0 0 0" xyz="0 0 0"/>
      <geometry>
        <box size="0.05 0.05 0.05"/>
        <!-- CHANGE LATER-->
      </geometry>
    </collision>
    <visual>
      <origin rpy="0 0 0" xyz="0 0 0"/>
      <geometry>
        <box size="0.05 0.05 0.05"/>
      </geometry>
      <material name="green"/>
    </visual>
    <inertial>
      <mass value="0.1"/>
      <origin rpy="0 0 0" xyz="0 0 0"/>
      <box_inertia m="0.1" x="0.1" y="0.1" z="0.1"/>
      <inertia ixx="1e-6" ixy="0" ixz="0" iyy="1e-6" iyz="0" izz="1e-6"/>
    </inertial>
  </link>
  <joint name="imu_joint" type="fixed">
    <axis xyz="0 1 0"/>
    <origin rpy="0 0 0" xyz="-0.3 0 1"/>
    <!-- CHANGE LATER-->
    <parent link="base_link"/>
    <child link="imu"/>
  </joint>
  <link name="hemisphere_gps">
    <collision>
      <origin rpy="0 0 0" xyz="0 0 0"/>
      <geometry>
        <box size="0.05 0.05 0.05"/>
        <!-- CHANGE LATER-->
      </geometry>
    </collision>
    <visual>
      <origin rpy="0 0 0" xyz="0 0 0"/>
      <geometry>
        <box size="0.05 0.05 0.05"/>
      </geometry>
      <material name="green"/>
    </visual>
    <inertial>
      <mass value="0.1"/>
      <origin rpy="0 0 0" xyz="0 0 0"/>
      <box_inertia m="0.1" x="0.1" y="0.1" z="0.1"/>
      <inertia ixx="1e-6" ixy="0" ixz="0" iyy="1e-6" iyz="0" izz="1e-6"/>
    </inertial>
  </link>
  <joint name="hemisphere_gps_joint" type="fixed">
    <axis xyz="0 1 0"/>
    <origin rpy="0 0 0" xyz="1.94 0 1.49"/>
    <!-- CHANGE LATER-->
    <parent link="base_link"/>
    <child link="hemisphere_gps"/>
  </joint>
  <link name="rtk_gps">
    <collision>
      <origin rpy="0 0 0" xyz="0 0 0"/>
      <geometry>
        <box size="0.05 0.05 0.05"/>
        <!-- CHANGE LATER-->
      </geometry>
    </collision>
    <visual>
      <origin rpy="0 0 0" xyz="0 0 0"/>
      <geometry>
        <box size="0.05 0.05 0.05"/>
      </geometry>
      <material name="green"/>
    </visual>
    <inertial>
      <mass value="0.1"/>
      <origin rpy="0 0 0" xyz="0 0 0"/>
      <box_inertia m="0.1" x="0.1" y="0.1" z="0.1"/>
      <inertia ixx="1e-6" ixy="0" ixz="0" iyy="1e-6" iyz="0" izz="1e-6"/>
    </inertial>
  </link>
  <joint name="rtk_gps_joint" type="fixed">
    <axis xyz="0 1 0"/>
    <origin rpy="0 0 0" xyz="0.3 0 2.21"/>
    <!-- CHANGE LATER-->
    <parent link="base_link"/>
    <child link="rtk_gps"/>
  </joint>
  <!-- Hokuyo Laser -->
  <!-- Using mesh example
  <link name="hokuyo">
    <collision>
      <origin xyz="0 0 0" rpy="0 0 0"/>
      <geometry>
    <box size="0.1 0.1 0.1"/>
      </geometry>
    </collision>

    <visual>
      <origin xyz="0 0 0" rpy="0 0 0"/>
      <geometry>
        <mesh filename="package://tractor_sim_description/meshes/hokuyo.dae"/>
      </geometry>
    </visual>

    <inertial>
      <mass value="1e-5" />
      <origin xyz="0 0 0" rpy="0 0 0"/>
      <inertia ixx="1e-6" ixy="0" ixz="0" iyy="1e-6" iyz="0" izz="1e-6" />
    </inertial>
  </link>

  <joint name="hokuyo_joint" type="fixed">
    <axis xyz="0 1 0" />
    <origin xyz=".15 0 .6" rpy="0 -.1 0"/>
    <parent link="chassis"/>
    <child link="hokuyo"/>
  </joint>
-->
</robot>
